Workbook

Sheet Sheet2
A1: Sec | B1: Row Labels | C1: Apr-2023 | D1: May-2023 | E1: Jun-2023 | F1: Jul-2023 | G1: Aug-2023 | H1: Sep-2023 | I1: Oct-2023 | J1: Nov-2023 | K1: Dec-2023 | L1: May-2024 | M1: Jun-2024 | N1: Jul-2024 | O1: Sep-2024 | P1: Aug-2024 | Q1: Oct-2024 | R1: Nov-2024 | S1: Dec-2024 | T1: Jan-2025 | U1: Feb-2025 | V1: Mar-2025 | W1: Apr-2025 | X1: May-2025 | Y1: Jun-2025 | Z1: Jul-2025 | AA1: Aug-2025 | AB1: Sep-2025 | AC1: Nov-2025 | AD1: Oct-2025 | AE1: Dec-2025 | AF1: Jan-2026 | AG1: Feb-2026 | AH1: Mar-2026 | AI1: Apr-2026 | AJ1: May-2026
A2: Rent | B2: Abohar 2337
A3: Rent | B3: ABOHAR 3196 | AC3: 39000 | AE3: 45000 | AF3: 45000 | AG3: 45000 | AH3: 45000 | AI3: 90000 | AJ3: 90000
A4: Rent | B4: AKBARPUR 3300 | AI4: 96428 | AJ4: 137754
A5: Rent | B5: AKOLA 2657 | C5: 74592 | D5: 74592 | E5: 74592 | F5: 74592 | G5: 74592 | H5: 74592 | I5: 74592 | J5: 74592 | K5: 74592 | L5: 74592 | M5: 74592 | N5: 74592 | O5: 74592 | P5: 74592 | Q5: 74592
A6: Rent | B6: Akola 1519 | AI6: 3658.9 | AJ6: 109767
A7: Rent | B7: Akola 1728
A8: Rent | B8: Akola 2353 | C8: 104583 | D8: 104583 | E8: 104583 | F8: 104583 | G8: 104583 | H8: 104583 | I8: 104583 | J8: 104583 | K8: 104583 | L8: 308892 | M8: 308892 | N8: 308892 | O8: 204309 | P8: 204309 | Q8: 102879 | R8: 102879 | S8: 102879 | T8: 102879 | U8: 211194 | V8: 211194 | W8: 211194 | X8: 211194 | Y8: 211194 | Z8: 211194 | AA8: 211194 | AB8: 108315 | AC8: 108315 | AD8: 108315 | AE8: 108315 | AF8: 102879 | AG8: 102879 | AH8: 102879 | AI8: 102879 | AJ8: 102879
A9: Rent | B9: Akola 2354
A10: Rent | B10: Akola 2362
A11: Rent | B11: Akola 2373
A12: Rent | B12: AKOLA 2516 | AI12: 65859 | AJ12: 109767
A13: Rent | B13: AKOLA 2528
A14: Rent | B14: AKOLA 2894 | L14: 170856 | M14: 170856 | N14: 170856 | P14: 67889
A15: Rent | B15: AKOLA 2908 | L15: 60288 | M15: 60288 | N15: 60288 | O15: 60288 | P15: 60288 | Q15: 60288
A16: Rent | B16: AKOLA 3069 | V16: 92872 | W16: 92872 | X16: 92872 | Y16: 92872 | Z16: 92872 | AA16: 92872 | AB16: 92872 | AC16: 92872 | AD16: 92872 | AE16: 92872 | AF16: 92872 | AG16: 92872 | AH16: 92872 | AI16: 228756 | AJ16: 228756
A17: Rent | B17: AKOLA 3222
A18: Rent | B18: AKOLA 3279 | AI18: 410350 | AJ18: 410350
A19: Rent | B19: AKOLA CON 3283 | AI19: 142013 | AJ19: 142013
A20: Rent | B20: ALWAR 3005 | Q20: 29661 | R20: 29661 | S20: 29661
A21: Rent | B21: ALWAR 3006 | O21: 12896 | Q21: 96720 | R21: 96720 | S21: 96720
A22: Rent | B22: AMETHI 2823 | J22: 20167 | K22: 55000
A23: Rent | B23: AMETHI 3115 | W23: 112700 | X23: 120750 | Y23: 120750 | Z23: 120750 | AA23: 120750 | AB23: 120750 | AC23: 120750 | AD23: 120750 | AE23: 120750 | AF23: 120750 | AG23: 120750
A24: Rent | B24: AMETHI 3293 | AI24: 136000 | AJ24: 136000
A25: Rent | B25: AMETHI 3351 | AJ25: 34066
A26: Rent | B26: AMRAVATI 3282 | AI26: 139400 | AJ26: 139400
A27: Rent | B27: AMRITSAR 2625 | C27: 65450
A28: Rent | B28: ANANTHASAGAR 2454
A29: Rent | B29: ANANTHASAGAR 2455
A30: Rent | B30: ANNUR 3076 | V30: 119786 | W30: 195440 | X30: 195440 | Y30: 195440 | Z30: 195440 | AA30: 195440 | AB30: 195440 | AC30: 195440 | AD30: 195440 | AE30: 195440 | AF30: 195440 | AG30: 27920
A31: Rent | B31: ANTAWADI 2549
A32: Rent | B32: ARUPPUKOTTAI 3053 | S32: 209032 | T32: 240000 | U32: 240000 | V32: 240000 | W32: -176000
A33: Rent | B33: ARUPPUKOTTAI 3210 | AE33: 373787 | AF33: 429163 | AG33: 429163 | AH33: 429163 | AI33: 429163 | AJ33: 429163
A34: Rent | B34: ARUPPUKOTTAI 3211 | AE34: 193390 | AF34: 285480 | AG34: 285480 | AH34: 285480 | AI34: 285480 | AJ34: 285480
A35: Rent | B35: ARUPPUKOTTAI 3218 | AE35: 602183 | AF35: 933383 | AG35: 933383 | AH35: 933383 | AI35: 933383 | AJ35: 933383
A36: Rent | B36: ARUPPUKOTTAI 3221 | AE36: 235759 | AF36: 487236 | AG36: 487236 | AH36: 487236 | AI36: 487236 | AJ36: 487236
A37: Rent | B37: Ashok Nagar 453 | C37: 197030 | D37: 197030 | E37: 197030 | F37: 197030 | G37: 197030 | H37: 197030 | I37: 197030 | J37: 197030 | K37: 197030 | L37: 197030 | M37: 197030 | N37: 197030 | O37: 197030 | P37: 197030 | Q37: 197030 | R37: 197030 | S37: 197030 | T37: 197030 | U37: 197030 | V37: 197030 | W37: 197030 | X37: 197030 | Y37: 197030 | Z37: 197030 | AA37: 197030 | AB37: 197030 | AC37: 197030 | AD37: 197030 | AE37: 197030 | AF37: 197030 | AG37: 197030 | AH37: 197030 | AI37: 197030 | AJ37: 197030
A38: Rent | B38: ASHOKNAGAR 2540 | C38: 227811 | D38: 227811 | E38: 227811 | F38: 227811 | G38: 227811 | H38: 227811 | I38: 227811 | J38: 78635 | K38: 78635 | L38: 157270 | M38: 78635 | N38: 78635 | O38: 78635 | P38: 78635 | Q38: 78635 | R38: 78635 | S38: 78635 | T38: 78635 | U38: 78635 | V38: 78635 | W38: 78635 | X38: 78635 | Y38: 78635 | Z38: 78635 | AA38: 78635 | AB38: 78635 | AC38: 78635 | AD38: 78635 | AE38: 66640 | AF38: 66640 | AG38: 66640 | AH38: 66640 | AI38: 66640 | AJ38: 66640
A39: Rent | B39: ASHOKNAGAR CON 3171 | Y39: 135878 | Z39: 135878 | AA39: 135878 | AB39: 135878 | AC39: 135878 | AD39: 135878 | AE39: 135878 | AF39: 135878 | AG39: 135878 | AH39: 135878 | AI39: 135878 | AJ39: 135878
A40: Rent | B40: ATMAKUR 2964 | L40: 158895 | M40: 158895 | N40: 158895 | P40: 158895
...

Sheet Sheet4
A3: Row Labels | B3: Sum of Apr-2023 | C3: Sum of May-2023 | D3: Sum of Jun-2023 | E3: Sum of Jul-2023 | F3: Sum of Aug-2023 | G3: Sum of Sep-2023 | H3: Sum of Oct-2023 | I3: Sum of Nov-2023 | J3: Sum of Dec-2023 | K3: Sum of Jan-2024 | L3: Sum of Feb-2024 | M3: Sum of Mar-2024 | N3: Sum of Apr-2024 | O3: Sum of May-2024 | P3: Sum of Jun-2024 | Q3: Sum of Jul-2024 | R3: Sum of Aug-2024 | S3: Sum of Sep-2024 | T3: Sum of Oct-2024 | U3: Sum of Nov-2024 | V3: Sum of Dec-2024 | W3: Sum of Jan-2025 | X3: Sum of Feb-2025 | Y3: Sum of Mar-2025 | Z3: Sum of Apr-2025 | AA3: Sum of May-2025 | AB3: Sum of Jun-2025 | AC3: Sum of Jul-2025 | AD3: Sum of Aug-2025 | AE3: Sum of Sep-2025 | AF3: Sum of Oct-2025 | AG3: Sum of Nov-2025 | AH3: Sum of Dec-2025 | AI3: Sum of Jan-2026 | AJ3: Sum of Feb-2026 | AK3: Sum of Mar-2026 | AL3: Sum of Apr-2026 | AM3: Sum of May-2026
A4: Abohar 2337
A5: ABOHAR 3196 | AG5: 39000 | AH5: 45000 | AI5: 45000 | AJ5: 45000 | AK5: 45000 | AL5: 90000 | AM5: 90000
A6: AKBARPUR 3300 | AL6: 96428 | AM6: 137754
A7: AKOLA 2657 | B7: 74592 | C7: 74592 | D7: 74592 | E7: 74592 | F7: 74592 | G7: 74592 | H7: 74592 | I7: 74592 | J7: 74592 | K7: 74592 | L7: 74592 | M7: 74592 | N7: 74592 | O7: 74592 | P7: 74592 | Q7: 74592 | R7: 74592 | S7: 74592 | T7: 74592
A8: Akola 1519 | AL8: 3658.9 | AM8: 109767
A9: Akola 1728
A10: Akola 2353 | B10: 104583 | C10: 104583 | D10: 104583 | E10: 104583 | F10: 104583 | G10: 104583 | H10: 104583 | I10: 104583 | J10: 104583 | K10: 199469 | L10: 308892 | M10: 308892 | N10: 308892 | O10: 308892 | P10: 308892 | Q10: 308892 | R10: 204309 | S10: 204309 | T10: 102879 | U10: 102879 | V10: 102879 | W10: 102879 | X10: 211194 | Y10: 211194 | Z10: 211194 | AA10: 211194 | AB10: 211194 | AC10: 211194 | AD10: 211194 | AE10: 108315 | AF10: 108315 | AG10: 108315 | AH10: 108315 | AI10: 102879 | AJ10: 102879 | AK10: 102879 | AL10: 102879 | AM10: 102879
A11: Akola 2354
A12: Akola 2362
A13: Akola 2373
A14: AKOLA 2516 | AL14: 65859 | AM14: 109767
A15: AKOLA 2528
A16: AKOLA 2894 | M16: 102967 | N16: 170856 | O16: 170856 | P16: 170856 | Q16: 170856 | R16: 67889
A17: AKOLA 2908 | M17: 19448 | N17: 60288 | O17: 60288 | P17: 60288 | Q17: 60288 | R17: 60288 | S17: 60288 | T17: 60288
A18: AKOLA 3069 | Y18: 92872 | Z18: 92872 | AA18: 92872 | AB18: 92872 | AC18: 92872 | AD18: 92872 | AE18: 92872 | AF18: 92872 | AG18: 92872 | AH18: 92872 | AI18: 92872 | AJ18: 92872 | AK18: 92872 | AL18: 228756 | AM18: 228756
A19: AKOLA 3222
A20: AKOLA 3279 | AL20: 410350 | AM20: 410350
A21: AKOLA CON 3283 | AL21: 142013 | AM21: 142013
A22: ALWAR 3005 | T22: 29661 | U22: 29661 | V22: 29661
A23: ALWAR 3006 | S23: 12896 | T23: 96720 | U23: 96720 | V23: 96720
A24: AMETHI 2823 | I24: 20167 | J24: 55000 | K24: 55000 | L24: 55000 | M24: 55000 | N24: 36667
A25: AMETHI 3115 | Z25: 112700 | AA25: 120750 | AB25: 120750 | AC25: 120750 | AD25: 120750 | AE25: 120750 | AF25: 120750 | AG25: 120750 | AH25: 120750 | AI25: 120750 | AJ25: 120750
A26: AMETHI 3293 | AL26: 136000 | AM26: 136000
A27: AMETHI 3351 | AM27: 34066
A28: AMRAVATI 3282 | AL28: 139400 | AM28: 139400
A29: AMRITSAR 2625 | B29: 65450
A30: ANANTHASAGAR 2454
A31: ANANTHASAGAR 2455
A32: ANNUR 3076 | Y32: 119786 | Z32: 195440 | AA32: 195440 | AB32: 195440 | AC32: 195440 | AD32: 195440 | AE32: 195440 | AF32: 195440 | AG32: 195440 | AH32: 195440 | AI32: 195440 | AJ32: 27920
A33: ANTAWADI 2549
A34: ARUPPUKOTTAI 3053 | V34: 209032 | W34: 240000 | X34: 240000 | Y34: 240000 | Z34: -176000
A35: ARUPPUKOTTAI 3210 | AH35: 373787 | AI35: 429163 | AJ35: 429163 | AK35: 429163 | AL35: 429163 | AM35: 429163
A36: ARUPPUKOTTAI 3211 | AH36: 193390 | AI36: 285480 | AJ36: 285480 | AK36: 285480 | AL36: 285480 | AM36: 285480
A37: ARUPPUKOTTAI 3218 | AH37: 602183 | AI37: 933383 | AJ37: 933383 | AK37: 933383 | AL37: 933383 | AM37: 933383
A38: ARUPPUKOTTAI 3221 | AH38: 235759 | AI38: 487236 | AJ38: 487236 | AK38: 487236 | AL38: 487236 | AM38: 487236
A39: Ashok Nagar 453 | B39: 197030 | C39: 197030 | D39: 197030 | E39: 197030 | F39: 197030 | G39: 197030 | H39: 197030 | I39: 197030 | J39: 197030 | K39: 197030 | L39: 197030 | M39: 197030 | N39: 197030 | O39: 197030 | P39: 197030 | Q39: 197030 | R39: 197030 | S39: 197030 | T39: 197030 | U39: 197030 | V39: 197030 | W39: 197030 | X39: 197030 | Y39: 197030 | Z39: 197030 | AA39: 197030 | AB39: 197030 | AC39: 197030 | AD39: 197030 | AE39: 197030 | AF39: 197030 | AG39: 197030 | AH39: 197030 | AI39: 197030 | AJ39: 197030 | AK39: 197030 | AL39: 197030 | AM39: 197030
A40: ASHOKNAGAR 2540 | B40: 227811 | C40: 227811 | D40: 227811 | E40: 227811 | F40: 227811 | G40: 227811 | H40: 227811 | I40: 78635 | J40: 78635 | K40: 78635 | L40: 78635 | M40: 78635 | N40: 78635 | O40: 157270 | P40: 78635 | Q40: 78635 | R40: 78635 | S40: 78635 | T40: 78635 | U40: 78635 | V40: 78635 | W40: 78635 | X40: 78635 | Y40: 78635 | Z40: 78635 | AA40: 78635 | AB40: 78635 | AC40: 78635 | AD40: 78635 | AE40: 78635 | AF40: 78635 | AG40: 78635 | AH40: 66640 | AI40: 66640 | AJ40: 66640 | AK40: 66640 | AL40: 66640 | AM40: 66640
A41: ASHOKNAGAR CON 3171 | AB41: 135878 | AC41: 135878 | AD41: 135878 | AE41: 135878 | AF41: 135878 | AG41: 135878 | AH41: 135878 | AI41: 135878 | AJ41: 135878 | AK41: 135878 | AL41: 135878 | AM41: 135878
A42: ATMAKUR 2964 | O42: 158895 | P42: 158895 | Q42: 158895 | R42: 158895
...

Sheet Summary
C3: Values | D3: Det
C4: Sum of FY 23-24 | E4: Sum of FY 24-25 | G4: Sum of FY 25-26 | I4: Total Sum of FY 23-24 | J4: Total Sum of FY 24-25 | K4: Total Sum of FY 25-26
A5: CMP ID | B5: Capacity | C5: Rent | D5: Rev | E5: Rent | F5: Rev | G5: Rent | H5: Rev | L5: 23-24 to 24-25 | M5: 24-25 TO 25-26
A6: Abohar 2337 | B6: 1733 | C6: 0 | D6: 0 | E6: 0 | F6: 0 | G6: 0 | H6: 0 | I6: 0 | J6: 0 | K6: 0 | L6: =E6/C6-1 -> #DIV/0! | M6: =G6/E6-1 -> #DIV/0!
A7: ABOHAR 3196 | B7: 1679 | C7: 0 | D7: 0 | E7: 0 | F7: 0 | G7: 219000 | H7: 416038.7 | I7: 0 | J7: 0 | K7: 635038.7 | L7: =E7/C7-1 -> #DIV/0! | M7: =G7/E7-1 -> #DIV/0!
A8: AKBARPUR 3300 | B8: 2551 | C8: 0 | D8: 0 | E8: 0 | F8: 0 | G8: 0 | H8: 0 | I8: 0 | J8: 0 | K8: 0 | L8: =E8/C8-1 -> #DIV/0! | M8: =G8/E8-1 -> #DIV/0!
A9: AKOLA 2657 | B9: 1554 | C9: 895104 | D9: 1274245.8 | E9: 522144 | F9: 1061498.1 | G9: 0 | H9: 0 | I9: 2169349.8 | J9: 1583642.1 | K9: 0 | L9: =E9/C9-1 -> -0.41666667 | M9: =G9/E9-1 -> -1
A10: Akola 1519 | B10: 871 | C10: 0 | D10: 0 | E10: 0 | F10: 0 | G10: 0 | H10: 0 | I10: 0 | J10: 0 | K10: 0 | L10: =E10/C10-1 -> #DIV/0! | M10: =G10/E10-1 -> #DIV/0!
A11: Akola 1728 | B11: 1005 | C11: 0 | D11: 0 | E11: 0 | F11: 0 | G11: 0 | H11: 0 | I11: 0 | J11: 0 | K11: 0 | L11: =E11/C11-1 -> #DIV/0! | M11: =G11/E11-1 -> #DIV/0!
A12: Akola 2353 | B12: 2485 | C12: 1758500 | D12: 2088187 | E12: 2478090 | F12: 2964305.6 | G12: 1797867 | H12: 1647622.9 | I12: 3846687 | J12: 5442395.6 | K12: 3445489.9 | L12: =E12/C12-1 -> 0.40920671 | M12: =G12/E12-1 -> -0.27449487
A13: Akola 2354 | B13: 833 | C13: 0 | D13: 0 | E13: 0 | F13: 0 | G13: 0 | H13: 0 | I13: 0 | J13: 0 | K13: 0 | L13: =E13/C13-1 -> #DIV/0! | M13: =G13/E13-1 -> #DIV/0!
A14: Akola 2362 | B14: 813 | C14: 0 | D14: 0 | E14: 0 | F14: 0 | G14: 0 | H14: 0 | I14: 0 | J14: 0 | K14: 0 | L14: =E14/C14-1 -> #DIV/0! | M14: =G14/E14-1 -> #DIV/0!
A15: Akola 2373 | B15: 871 | C15: 0 | D15: 0 | E15: 0 | F15: 0 | G15: 0 | H15: 0 | I15: 0 | J15: 0 | K15: 0 | L15: =E15/C15-1 -> #DIV/0! | M15: =G15/E15-1 -> #DIV/0!
A16: AKOLA 2516 | B16: 871 | C16: 0 | D16: 0 | E16: 0 | F16: 1166748.3 | G16: 0 | H16: 0 | I16: 0 | J16: 1166748.3 | K16: 0 | L16: =E16/C16-1 -> #DIV/0! | M16: =G16/E16-1 -> #DIV/0!
A17: AKOLA 2528 | B17: 813 | C17: 0 | D17: 0 | E17: 0 | F17: 0 | G17: 0 | H17: 0 | I17: 0 | J17: 0 | K17: 0 | L17: =E17/C17-1 -> #DIV/0! | M17: =G17/E17-1 -> #DIV/0!
... A706: YAVATMAL 3363 | B706: 2500 | C706: 0 | D706: 0 | E706: 0 | F706: 0 | G706: 0 | H706: 0 | I706: 0 | J706: 0 | K706: 0 | L706: =E706/C706-1 -> #DIV/0! | M706: =G706/E706-1 -> #DIV/0!
A707: Grand Total | C707: 3.2348876e+08 | D707: 4.7347988e+08 | E707: 4.5590143e+08 | F707: 7.2245523e+08 | G707: 4.5636892e+08 | H707: 7.7090935e+08 | I707: 7.9696864e+08 | J707: 1.1783567e+09 | K707: 1.2272783e+09 | L707: =E707/C707-1 -> 0.40932694 | M707: =G707/E707-1 -> 0.0010254142

Sheet RAW Data
A1: Details | B1: CMP ID | C1: Capacity | D1: Cost Center | E1: 45017 | F1: 45047 | G1: 45078 | H1: 45108 | I1: 45139 | J1: 45170 | K1: 45200 | L1: 45231 | M1: 45261 | N1: 45292 | O1: 45323 | P1: 45352 | Q1: FY 23-24 | R1: 45383 | S1: 45413 | T1: 45444 | U1: 45474 | V1: 45505 | W1: 45536 | X1: 45566 | Y1: 45597 | Z1: 45627 | AA1: 45658 | AB1: 45689 | AC1: 45717 | AD1: FY 24-25 | AE1: 45748 | AF1: 45778 | AG1: 45809 | AH1: 45839 | AI1: 45870 | AJ1: 45901 | AK1: 45931 | AL1: 45962 | AM1: 45992 | AN1: 46023 | AO1: 46054 | AP1: 46082 | AQ1: FY 25-26 | AR1: 46113 | AS1: 46143 | AT1: FY 26-27
A2: Rent | B2: Abohar 2337 | C2: =VLOOKUP(B2,'Rent Data'!D:I,6,0) -> 1733 | D2: NULL | Q2: =SUM(E2:P2) -> 0 | AD2: =SUM(R2:AC2) -> 0 | AQ2: =SUM(AE2:AP2) -> 0 | AT2: =SUM(AR2:AS2) -> 0
A3: Rent | B3: ABOHAR 3196 | C3: =VLOOKUP(B3,'Rent Data'!D:I,6,0) -> 1679 | D3: WH-LE-3196 | Q3: =SUM(E3:P3) -> 0 | AD3: =SUM(R3:AC3) -> 0 | AL3: 39000 | AM3: 45000 | AN3: 45000 | AO3: 45000 | AP3: 45000 | AQ3: =SUM(AE3:AP3) -> 219000 | AR3: 90000 | AS3: 90000 | AT3: =SUM(AR3:AS3) -> 180000
A4: Rent | B4: AKBARPUR 3300 | C4: =VLOOKUP(B4,'Rent Data'!D:I,6,0) -> 2551 | D4: WH-LE-3300 | Q4: =SUM(E4:P4) -> 0 | AD4: =SUM(R4:AC4) -> 0 | AQ4: =SUM(AE4:AP4) -> 0 | AR4: 96428 | AS4: 137754 | AT4: =SUM(AR4:AS4) -> 234182
A5: Rent | B5: AKOLA 2657 | C5: =VLOOKUP(B5,'Rent Data'!D:I,6,0) -> 1554 | D5: WH-LE-2657 | E5: 74592 | F5: 74592 | G5: 74592 | H5: 74592 | I5: 74592 | J5: 74592 | K5: 74592 | L5: 74592 | M5: 74592 | N5: 74592 | O5: 74592 | P5: 74592 | Q5: =SUM(E5:P5) -> 895104 | R5: 74592 | S5: 74592 | T5: 74592 | U5: 74592 | V5: 74592 | W5: 74592 | X5: 74592 | AD5: =SUM(R5:AC5) -> 522144 | AQ5: =SUM(AE5:AP5) -> 0 | AT5: =SUM(AR5:AS5) -> 0
A6: Rent | B6: Akola 1519 | C6: =VLOOKUP(B6,'Rent Data'!D:I,6,0) -> 871 | D6: WH-LE-1519 | Q6: =SUM(E6:P6) -> 0 | AD6: =SUM(R6:AC6) -> 0 | AQ6: =SUM(AE6:AP6) -> 0 | AR6: 3658.9 | AS6: 109767 | AT6: =SUM(AR6:AS6) -> 113425.9
A7: Rent | B7: Akola 1728 | C7: =VLOOKUP(B7,'Rent Data'!D:I,6,0) -> 1005 | D7: NULL | Q7: =SUM(E7:P7) -> 0 | AD7: =SUM(R7:AC7) -> 0 | AQ7: =SUM(AE7:AP7) -> 0 | AT7: =SUM(AR7:AS7) -> 0
A8: Rent | B8: Akola 2353 | C8: =VLOOKUP(B8,'Rent Data'!D:I,6,0) -> 2485 | D8: WH-LE-2353 | E8: 104583 | F8: 104583 | G8: 104583 | H8: 104583 | I8: 104583 | J8: 104583 | K8: 104583 | L8: 104583 | M8: 104583 | N8: 199469 | O8: 308892 | P8: 308892 | Q8: =SUM(E8:P8) -> 1758500 | R8: 308892 | S8: 308892 | T8: 308892 | U8: 308892 | V8: 204309 | W8: 204309 | X8: 102879 | Y8: 102879 | Z8: 102879 | AA8: 102879 | AB8: 211194 | AC8: 211194 | AD8: =SUM(R8:AC8) -> 2478090 | AE8: 211194 | AF8: 211194 | AG8: 211194 | AH8: 211194 | AI8: 211194 | AJ8: 108315 | AK8: 108315 | AL8: 108315 | AM8: 108315 | AN8: 102879 | AO8: 102879 | AP8: 102879 | AQ8: =SUM(AE8:AP8) -> 1797867 | AR8: 102879 | AS8: 102879 | AT8: =SUM(AR8:AS8) -> 205758
A9: Rent | B9: Akola 2354 | C9: =VLOOKUP(B9,'Rent Data'!D:I,6,0) -> 833 | D9: NULL | Q9: =SUM(E9:P9) -> 0 | AD9: =SUM(R9:AC9) -> 0 | AQ9: =SUM(AE9:AP9) -> 0 | AT9: =SUM(AR9:AS9) -> 0
A10: Rent | B10: Akola 2362 | C10: =VLOOKUP(B10,'Rent Data'!D:I,6,0) -> 813 | D10: NULL | Q10: =SUM(E10:P10) -> 0 | AD10: =SUM(R10:AC10) -> 0 | AQ10: =SUM(AE10:AP10) -> 0 | AT10: =SUM(AR10:AS10) -> 0
A11: Rent | B11: Akola 2373 | C11: =VLOOKUP(B11,'Rent Data'!D:I,6,0) -> 871 | D11: NULL | Q11: =SUM(E11:P11) -> 0 | AD11: =SUM(R11:AC11) -> 0 | AQ11: =SUM(AE11:AP11) -> 0 | AT11: =SUM(AR11:AS11) -> 0
A12: Rent | B12: AKOLA 2516 | C12: =VLOOKUP(B12,'Rent Data'!D:I,6,0) -> 871 | D12: WH-FR-2516 | Q12: =SUM(E12:P12) -> 0 | AD12: =SUM(R12:AC12) -> 0 | AQ12: =SUM(AE12:AP12) -> 0 | AR12: 65859 | AS12: 109767 | AT12: =SUM(AR12:AS12) -> 175626
A13: Rent | B13: AKOLA 2528 | C13: =VLOOKUP(B13,'Rent Data'!D:I,6,0) -> 813 | D13: NULL | Q13: =SUM(E13:P13) -> 0 | AD13: =SUM(R13:AC13) -> 0 | AQ13: =SUM(AE13:AP13) -> 0 | AT13: =SUM(AR13:AS13) -> 0
A14: Rent | B14: AKOLA 2894 | C14: =VLOOKUP(B14,'Rent Data'!D:I,6,0) -> 2043 | D14: WH-FR-2894 | P14: 102967 | Q14: =SUM(E14:P14) -> 102967 | R14: 170856 | S14: 170856 | T14: 170856 | U14: 170856 | V14: 67889 | AD14: =SUM(R14:AC14) -> 751313 | AQ14: =SUM(AE14:AP14) -> 0 | AT14: =SUM(AR14:AS14) -> 0
A15: Rent | B15: AKOLA 2908 | C15: =VLOOKUP(B15,'Rent Data'!D:I,6,0) -> 1675 | D15: WH-LE-2908 | P15: 19448 | Q15: =SUM(E15:P15) -> 19448 | R15: 60288 | S15: 60288 | T15: 60288 | U15: 60288 | V15: 60288 | W15: 60288 | X15: 60288 | AD15: =SUM(R15:AC15) -> 422016 | AQ15: =SUM(AE15:AP15) -> 0 | AT15: =SUM(AR15:AS15) -> 0
A16: Rent | B16: AKOLA 3069 | C16: =VLOOKUP(B16,'Rent Data'!D:I,6,0) -> 2381 | D16: WH-LE-3069 | Q16: =SUM(E16:P16) -> 0 | AC16: 92872 | AD16: =SUM(R16:AC16) -> 92872 | AE16: 92872 | AF16: 92872 | AG16: 92872 | AH16: 92872 | AI16: 92872 | AJ16: 92872 | AK16: 92872 | AL16: 92872 | AM16: 92872 | AN16: 92872 | AO16: 92872 | AP16: 92872 | AQ16: =SUM(AE16:AP16) -> 1114464 | AR16: 228756 | AS16: 228756 | AT16: =SUM(AR16:AS16) -> 457512
A17: Rent | B17: AKOLA 3222 | C17: =VLOOKUP(B17,'Rent Data'!D:I,6,0) -> 2485 | D17: WH-LE-3222 | Q17: =SUM(E17:P17) -> 0 | AD17: =SUM(R17:AC17) -> 0 | AQ17: =SUM(AE17:AP17) -> 0 | AT17: =SUM(AR17:AS17) -> 0
A18: Rent | B18: AKOLA 3279 | C18: =VLOOKUP(B18,'Rent Data'!D:I,6,0) -> 2000 | D18: WH-LE-3279 | Q18: =SUM(E18:P18) -> 0 | AD18: =SUM(R18:AC18) -> 0 | AQ18: =SUM(AE18:AP18) -> 0 | AR18: 410350 | AS18: 410350 | AT18: =SUM(AR18:AS18) -> 820700
A19: Rent | B19: AKOLA CON 3283 | C19: =VLOOKUP(B19,'Rent Data'!D:I,6,0) -> 3156 | D19: WH-LE-3283 | Q19: =SUM(E19:P19) -> 0 | AD19: =SUM(R19:AC19) -> 0 | AQ19: =SUM(AE19:AP19) -> 0 | AR19: 142013 | AS19: 142013 | AT19: =SUM(AR19:AS19) -> 284026
A20: Rent | B20: ALWAR 3005 | C20: =VLOOKUP(B20,'Rent Data'!D:I,6,0) -> 761 | D20: WH-LE-3005 | Q20: =SUM(E20:P20) -> 0 | X20: 29661 | Y20: 29661 | Z20: 29661 | AD20: =SUM(R20:AC20) -> 88983 | AQ20: =SUM(AE20:AP20) -> 0 | AT20: =SUM(AR20:AS20) -> 0
A21: Rent | B21: ALWAR 3006 | C21: =VLOOKUP(B21,'Rent Data'!D:I,6,0) -> 1653 | D21: WH-LE-3006 | Q21: =SUM(E21:P21) -> 0 | W21: 12896 | X21: 96720 | Y21: 96720 | Z21: 96720 | AD21: =SUM(R21:AC21) -> 303056 | AQ21: =SUM(AE21:AP21) -> 0 | AT21: =SUM(AR21:AS21) -> 0
A22: Rent | B22: AMETHI 2823 | C22: =VLOOKUP(B22,'Rent Data'!D:I,6,0) -> 1833 | D22: WH-LE-2823 | L22: 20167 | M22: 55000 | N22: 55000 | O22: 55000 | P22: 55000 | Q22: =SUM(E22:P22) -> 240167 | R22: 36667 | AD22: =SUM(R22:AC22) -> 36667 | AQ22: =SUM(AE22:AP22) -> 0 | AT22: =SUM(AR22:AS22) -> 0
A23: Rent | B23: AMETHI 3115 | C23: =VLOOKUP(B23,'Rent Data'!D:I,6,0) -> 2875 | D23: WH-LE-3115 | Q23: =SUM(E23:P23) -> 0 | AD23: =SUM(R23:AC23) -> 0 | AE23: 112700 | AF23: 120750 | AG23: 120750 | AH23: 120750 | AI23: 120750 | AJ23: 120750 | AK23: 120750 | AL23: 120750 | AM23: 120750 | AN23: 120750 | AO23: 120750 | AQ23: =SUM(AE23:AP23) -> 1320200 | AT23: =SUM(AR23:AS23) -> 0
A24: Rent | B24: AMETHI 3293 | C24: =VLOOKUP(B24,'Rent Data'!D:I,6,0) -> 2875 | D24: WH-LE-3293 | Q24: =SUM(E24:P24) -> 0 | AD24: =SUM(R24:AC24) -> 0 | AQ24: =SUM(AE24:AP24) -> 0 | AR24: 136000 | AS24: 136000 | AT24: =SUM(AR24:AS24) -> 272000
A25: Rent | B25: AMETHI 3351 | C25: =VLOOKUP(B25,'Rent Data'!D:I,6,0) -> 1330 | D25: WH-LE-3351 | Q25: =SUM(E25:P25) -> 0 | AD25: =SUM(R25:AC25) -> 0 | AQ25: =SUM(AE25:AP25) -> 0 | AS25: 34066 | AT25: =SUM(AR25:AS25) -> 34066
A26: Rent | B26: AMRAVATI 3282 | C26: =VLOOKUP(B26,'Rent Data'!D:I,6,0) -> 2904 | D26: WH-LE-3282 | Q26: =SUM(E26:P26) -> 0 | AD26: =SUM(R26:AC26) -> 0 | AQ26: =SUM(AE26:AP26) -> 0 | AR26: 139400 | AS26: 139400 | AT26: =SUM(AR26:AS26) -> 278800
A27: Rent | B27: AMRITSAR 2625 | C27: =VLOOKUP(B27,'Rent Data'!D:I,6,0) -> 1983 | D27: NULL | E27: 65450 | Q27: =SUM(E27:P27) -> 65450 | AD27: =SUM(R27:AC27) -> 0 | AQ27: =SUM(AE27:AP27) -> 0 | AT27: =SUM(AR27:AS27) -> 0
A28: Rent | B28: ANANTHASAGAR 2454 | C28: =VLOOKUP(B28,'Rent Data'!D:I,6,0) -> 5255 | D28: NULL | Q28: =SUM(E28:P28) -> 0 | AD28: =SUM(R28:AC28) -> 0 | AQ28: =SUM(AE28:AP28) -> 0 | AT28: =SUM(AR28:AS28) -> 0
A29: Rent | B29: ANANTHASAGAR 2455 | C29: =VLOOKUP(B29,'Rent Data'!D:I,6,0) -> 5255 | D29: NULL | Q29: =SUM(E29:P29) -> 0 | AD29: =SUM(R29:AC29) -> 0 | AQ29: =SUM(AE29:AP29) -> 0 | AT29: =SUM(AR29:AS29) -> 0
A30: Rent | B30: ANNUR 3076 | C30: =VLOOKUP(B30,'Rent Data'!D:I,6,0) -> 3723 | D30: WH-LE-3076 | Q30: =SUM(E30:P30) -> 0 | AC30: 119786 | AD30: =SUM(R30:AC30) -> 119786 | AE30: 195440 | AF30: 195440 | AG30: 195440 | AH30: 195440 | AI30: 195440 | AJ30: 195440 | AK30: 195440 | AL30: 195440 | AM30: 195440 | AN30: 195440 | AO30: 27920 | AQ30: =SUM(AE30:AP30) -> 1982320 | AT30: =SUM(AR30:AS30) -> 0
A31: Rent | B31: ANTAWADI 2549 | C31: =VLOOKUP(B31,'Rent Data'!D:I,6,0) -> 4215 | D31: NULL | Q31: =SUM(E31:P31) -> 0 | AD31: =SUM(R31:AC31) -> 0 | AQ31: =SUM(AE31:AP31) -> 0 | AT31: =SUM(AR31:AS31) -> 0
A32: Rent | B32: ARUPPUKOTTAI 3053 | C32: =VLOOKUP(B32,'Rent Data'!D:I,6,0) -> 4000 | D32: WH-LE-3053 | Q32: =SUM(E32:P32) -> 0 | Z32: 209032 | AA32: 240000 | AB32: 240000 | AC32: 240000 | AD32: =SUM(R32:AC32) -> 929032 | AE32: -176000 | AQ32: =SUM(AE32:AP32) -> -176000 | AT32: =SUM(AR32:AS32) -> 0
A33: Rent | B33: ARUPPUKOTTAI 3210 | C33: =VLOOKUP(B33,'Rent Data'!D:I,6,0) -> 10218 | D33: WH-LE-3210 | Q33: =SUM(E33:P33) -> 0 | AD33: =SUM(R33:AC33) -> 0 | AM33: 373787 | AN33: 429163 | AO33: 429163 | AP33: 429163 | AQ33: =SUM(AE33:AP33) -> 1661276 | AR33: 429163 | AS33: 429163 | AT33: =SUM(AR33:AS33) -> 858326
A34: Rent | B34: ARUPPUKOTTAI 3211 | C34: =VLOOKUP(B34,'Rent Data'!D:I,6,0) -> 3660 | D34: WH-LE-3211 | Q34: =SUM(E34:P34) -> 0 | AD34: =SUM(R34:AC34) -> 0 | AM34: 193390 | AN34: 285480 | AO34: 285480 | AP34: 285480 | AQ34: =SUM(AE34:AP34) -> 1049830 | AR34: 285480 | AS34: 285480 | AT34: =SUM(AR34:AS34) -> 570960
A35: Rent | B35: ARUPPUKOTTAI 3218 | C35: =VLOOKUP(B35,'Rent Data'!D:I,6,0) -> 23047 | D35: WH-LE-3218 | Q35: =SUM(E35:P35) -> 0 | AD35: =SUM(R35:AC35) -> 0 | AM35: 602183 | AN35: 933383 | AO35: 933383 | AP35: 933383 | AQ35: =SUM(AE35:AP35) -> 3402332 | AR35: 933383 | AS35: 933383 | AT35: =SUM(AR35:AS35) -> 1866766
A36: Rent | B36: ARUPPUKOTTAI 3221 | C36: =VLOOKUP(B36,'Rent Data'!D:I,6,0) -> 10827 | D36: WH-LE-3221 | Q36: =SUM(E36:P36) -> 0 | AD36: =SUM(R36:AC36) -> 0 | AM36: 235759 | AN36: 487236 | AO36: 487236 | AP36: 487236 | AQ36: =SUM(AE36:AP36) -> 1697467 | AR36: 487236 | AS36: 487236 | AT36: =SUM(AR36:AS36) -> 974472
A37: Rent | B37: Ashok Nagar 453 | C37: =VLOOKUP(B37,'Rent Data'!D:I,6,0) -> 2169 | D37: WH-LE-453 | E37: 197030 | F37: 197030 | G37: 197030 | H37: 197030 | I37: 197030 | J37: 197030 | K37: 197030 | L37: 197030 | M37: 197030 | N37: 197030 | O37: 197030 | P37: 197030 | Q37: =SUM(E37:P37) -> 2364360 | R37: 197030 | S37: 197030 | T37: 197030 | U37: 197030 | V37: 197030 | W37: 197030 | X37: 197030 | Y37: 197030 | Z37: 197030 | AA37: 197030 | AB37: 197030 | AC37: 197030 | AD37: =SUM(R37:AC37) -> 2364360 | AE37: 197030 | AF37: 197030 | AG37: 197030 | AH37: 197030 | AI37: 197030 | AJ37: 197030 | AK37: 197030 | AL37: 197030 | AM37: 197030 | AN37: 197030 | AO37: 197030 | AP37: 197030 | AQ37: =SUM(AE37:AP37) -> 2364360 | AR37: 197030 | AS37: 197030 | AT37: =SUM(AR37:AS37) -> 394060
A38: Rent | B38: ASHOKNAGAR 2540 | C38: =VLOOKUP(B38,'Rent Data'!D:I,6,0) -> 4214 | D38: WH-LE-2540 | E38: 227811 | F38: 227811 | G38: 227811 | H38: 227811 | I38: 227811 | J38: 227811 | K38: 227811 | L38: 78635 | M38: 78635 | N38: 78635 | O38: 78635 | P38: 78635 | Q38: =SUM(E38:P38) -> 1987852 | R38: 78635 | S38: 157270 | T38: 78635 | U38: 78635 | V38: 78635 | W38: 78635 | X38: 78635 | Y38: 78635 | Z38: 78635 | AA38: 78635 | AB38: 78635 | AC38: 78635 | AD38: =SUM(R38:AC38) -> 1022255 | AE38: 78635 | AF38: 78635 | AG38: 78635 | AH38: 78635 | AI38: 78635 | AJ38: 78635 | AK38: 78635 | AL38: 78635 | AM38: 66640 | AN38: 66640 | AO38: 66640 | AP38: 66640 | AQ38: =SUM(AE38:AP38) -> 895640 | AR38: 66640 | AS38: 66640 | AT38: =SUM(AR38:AS38) -> 133280
A39: Rent | B39: ASHOKNAGAR CON 3171 | C39: =VLOOKUP(B39,'Rent Data'!D:I,6,0) -> 5032 | D39: WH-LE-3171 | Q39: =SUM(E39:P39) -> 0 | AD39: =SUM(R39:AC39) -> 0 | AG39: 135878 | AH39: 135878 | AI39: 135878 | AJ39: 135878 | AK39: 135878 | AL39: 135878 | AM39: 135878 | AN39: 135878 | AO39: 135878 | AP39: 135878 | AQ39: =SUM(AE39:AP39) -> 1358780 | AR39: 135878 | AS39: 135878 | AT39: =SUM(AR39:AS39) -> 271756
A40: Rent | B40: ATMAKUR 2964 | C40: =VLOOKUP(B40,'Rent Data'!D:I,6,0) -> 1605 | D40: WH-LE-2964 | Q40: =SUM(E40:P40) -> 0 | S40: 158895 | T40: 158895 | U40: 158895 | V40: 158895 | AD40: =SUM(R40:AC40) -> 635580 | AQ40: =SUM(AE40:AP40) -> 0 | AT40: =SUM(AR40:AS40) -> 0
...

Sheet Rent Data
I1: 4015718 | J1: 16130964 | K1: 19251206 | L1: 19044554 | M1: 18447104 | N1: 18370198 | O1: 17577005 | P1: 17550465 | Q1: 17788476 | R1: 18261128 | S1: 14723230 | T1: 14004904 | U1: 14212569 | V1: 14513797 | W1: 19457981 | X1: 19644394 | Y1: 18989995 | Z1: 18536484 | AA1: 17730112 | AB1: 18055737 | AC1: 18154343 | AD1: 17779994 | AE1: 18764053 | AF1: 18158619 | AG1: 17776594 | AH1: 22596804 | AI1: 27766948 | AJ1: 28373833 | AK1: 28073470 | AL1: 27123605 | AM1: 26678379 | AN1: 26443496 | AO1: 25400646 | AP1: 25936637 | AQ1: 26298035 | AR1: 28555547 | AS1: 30241363 | AT1: 34328334 | AU1: 45450847 | AV1: 45901249 | AW1: 45082081 | AX1: 43103628 | AY1: 40676904 | AZ1: 37638459 | BA1: 36519093 | BB1: 34725245 | BC1: 31964049 | BD1: 30792238 | BE1: 29719305 | BF1: 33515822 | BG1: 41093928 | BH1: 40893364 | BI1: 40193164 | BJ1: 40063430 | BK1: 39008234 | BL1: 37393064 | BM1: 36901047 | BN1: 37370970 | BO1: 38368850 | BP1: 36460629 | BQ1: 35106417 | BR1: 36646282 | BS1: 46833759 | BT1: 48486278 | BU1: =SUBTOTAL(9,BU3:BU1048576) -> 2.053618e+08 | BV1: =SUBTOTAL(9,BV3:BV1048576) -> 2.175621e+08 | BW1: =SUBTOTAL(9,BW3:BW1048576) -> 3.2348876e+08 | BX1: =SUBTOTAL(9,BX3:BX1048576) -> 4.5590143e+08 | BY1: =SUBTOTAL(9,BY3:BY1048576) -> 4.5636892e+08 | BZ1: =SUBTOTAL(9,BZ3:BZ1048576) -> 1.3196632e+08
A2: Godown ID | B2: State Name | C2: Location Name | D2: CMP Name | E2: Godown No | F2: Address | G2: Start Date | H2: Close Date | I2: Godown Capacity | J2: Apr-2021 | K2: May-2021 | L2: Jun-2021 | M2: Jul-2021 | N2: Aug-2021 | O2: Sep-2021 | P2: Oct-2021 | Q2: Nov-2021 | R2: Dec-2021 | S2: Jan-2022 | T2: Feb-2022 | U2: Mar-2022 | V2: Apr-2022 | W2: May-2022 | X2: Jun-2022 | Y2: Jul-2022 | Z2: Aug-2022 | AA2: Sep-2022 | AB2: Oct-2022 | AC2: Nov-2022 | AD2: Dec-2022 | AE2: Jan-2023 | AF2: Feb-2023 | AG2: Mar-2023 | AH2: Apr-2023 | AI2: May-2023 | AJ2: Jun-2023 | AK2: Jul-2023 | AL2: Aug-2023 | AM2: Sep-2023 | AN2: Oct-2023 | AO2: Nov-2023 | AP2: Dec-2023 | AQ2: Jan-2024 | AR2: Feb-2024 | AS2: Mar-2024 | AT2: Apr-2024 | AU2: May-2024 | AV2: Jun-2024 | AW2: Jul-2024 | AX2: Aug-2024 | AY2: Sep-2024 | AZ2: Oct-2024 | BA2: Nov-2024 | BB2: Dec-2024 | BC2: Jan-2025 | BD2: Feb-2025 | BE2: Mar-2025 | BF2: Apr-2025 | BG2: May-2025 | BH2: Jun-2025 | BI2: Jul-2025 | BJ2: Aug-2025 | BK2: Sep-2025 | BL2: Oct-2025 | BM2: Nov-2025 | BN2: Dec-2025 | BO2: Jan-2026 | BP2: Feb-2026 | BQ2: Mar-2026 | BR2: Apr-2026 | BS2: May-2026 | BT2: Jun-2026 | BU2: FY 21-22 | BV2: FY 22-23 | BW2: FY 23-24 | BX2: FY 24-25 | BY2: FY 25-26 | BZ2: FY 26-27
A3: 6772 | B3: Andhra Pradesh - South coastal | C3: Atmakur | D3: ATMAKUR 2964 | E3: A | F3: K STAR RURAL FARMERS WAREHOUSE,GODOWN NO-A,SY NO 23/4,KARIVENA(V),ATMAKUR(M),KURNOOL-DIST,ANDHRA PRADESH-518422 | G3: 25-Apr-2024 | H3: 31-Aug-2024 | I3: 1605 | AU3: 52965 | AV3: 52965 | AW3: 52965 | AX3: 52965 | BU3: =SUM(J3:U3) -> 0 | BV3: =SUM(V3:AG3) -> 0 | BW3: =SUM(AH3:AS3) -> 0 | BX3: =SUM(AT3:BE3) -> 211860 | BY3: =SUM(BF3:BQ3) -> 0 | BZ3: =SUM(BR3:BT3) -> 0 | CA3: =BV3/BU3 -> #DIV/0!
A4: 6773 | B4: Andhra Pradesh - South coastal | C4: Atmakur | D4: ATMAKUR 2964 | E4: B | F4: K STAR RURAL FARMERS WAREHOUSE,GODOWN NO-B,SY NO 23/4,KARIVENA(V),ATMAKUR(M),KURNOOL-DIST,ANDHRA PRADESH-518422 | G4: 25-Apr-2024 | H4: 31-Aug-2024 | I4: 1605 | AU4: 52965 | AV4: 52965 | AW4: 52965 | AX4: 52965 | BU4: =SUM(J4:U4) -> 0 | BV4: =SUM(V4:AG4) -> 0 | BW4: =SUM(AH4:AS4) -> 0 | BX4: =SUM(AT4:BE4) -> 211860 | BY4: =SUM(BF4:BQ4) -> 0 | BZ4: =SUM(BR4:BT4) -> 0 | CA4: =BV4/BU4 -> #DIV/0!
A5: 6774 | B5: Andhra Pradesh - South coastal | C5: Atmakur | D5: ATMAKUR 2964 | E5: C | F5: K STAR RURAL FARMERS WAREHOUSE,GODOWN NO-C,SY NO 23/4,KARIVENA(V),ATMAKUR(M),KURNOOL-DIST,ANDHRA PRADESH-518422 | G5: 25-Apr-2024 | H5: 31-Aug-2024 | I5: 1605 | AU5: 52965 | AV5: 52965 | AW5: 52965 | AX5: 52965 | BU5: =SUM(J5:U5) -> 0 | BV5: =SUM(V5:AG5) -> 0 | BW5: =SUM(AH5:AS5) -> 0 | BX5: =SUM(AT5:BE5) -> 211860 | BY5: =SUM(BF5:BQ5) -> 0 | BZ5: =SUM(BR5:BT5) -> 0 | CA5: =BV5/BU5 -> #DIV/0!
A6: 7420 | B6: Andhra Pradesh - South coastal | C6: ETUKURU | D6: ETUKURU 3334 | E6: 1 | F6: ANJANI COTTON PVT LTD, GODOWN NO. 1, D NO. 8/215/4, ANANTHAVARAPADU ROAD, ETUKURU - VILLAGE, GUNTUR, ANDHRA PRADESH - 522017 | G6: 24-Apr-2026 | I6: 1917 | BR6: 4791.6667 | BS6: 143750 | BT6: 143750 | BU6: =SUM(J6:U6) -> 0 | BV6: =SUM(V6:AG6) -> 0 | BW6: =SUM(AH6:AS6) -> 0 | BX6: =SUM(AT6:BE6) -> 0 | BY6: =SUM(BF6:BQ6) -> 0 | BZ6: =SUM(BR6:BT6) -> 292291.67 | CA6: =BV6/BU6 -> #DIV/0!
A7: 7395 | B7: Andhra Pradesh - South coastal | C7: GANAPAVARAM | D7: GANAPAVARAM 3317 | E7: 2 | F7: TIRUMALA TURBO LUBES PRIVATE LIMITED GODOWN NO - 2, D.NO - 354, GANAPAVARAM VILLAGE, NADENDLA MANDAL, PALNADU - DIST, ANDHRA PRADESH - 522619 | G7: 15-Apr-2026 | I7: 2000 | BR7: 44800 | BS7: 84000 | BT7: 84000 | BU7: =SUM(J7:U7) -> 0 | BV7: =SUM(V7:AG7) -> 0 | BW7: =SUM(AH7:AS7) -> 0 | BX7: =SUM(AT7:BE7) -> 0 | BY7: =SUM(BF7:BQ7) -> 0 | BZ7: =SUM(BR7:BT7) -> 212800 | CA7: =BV7/BU7 -> #DIV/0!
A8: 4876 | B8: Andhra Pradesh - South coastal | C8: Guntur | D8: Guntur 1872 | E8: 2 | F8: RAMYA COLD STORAGE PVT LTD Lalpuram (village), By-Pass, D.NO:558, Guntur (Rural Mandal), Guntur (Dist), PIN:522005, A.P | G8: 27-Apr-2018 | I8: 1800 | BU8: =SUM(J8:U8) -> 0 | BV8: =SUM(V8:AG8) -> 0 | BW8: =SUM(AH8:AS8) -> 0 | BX8: =SUM(AT8:BE8) -> 0 | BY8: =SUM(BF8:BQ8) -> 0 | BZ8: =SUM(BR8:BT8) -> 0 | CA8: =BV8/BU8 -> #DIV/0!
A9: 4987 | B9: Andhra Pradesh - South coastal | C9: Guntur | D9: Guntur 1936 | E9: 1 | F9: JAYSAM ESTATES, D.No.9-354, Pulladigunta, Vatticherukuru (Mandal), Guntur District, Pin.522017, A.P. | G9: 22-Oct-2018 | I9: 1109 | BU9: =SUM(J9:U9) -> 0 | BV9: =SUM(V9:AG9) -> 0 | BW9: =SUM(AH9:AS9) -> 0 | BX9: =SUM(AT9:BE9) -> 0 | BY9: =SUM(BF9:BQ9) -> 0 | BZ9: =SUM(BR9:BT9) -> 0 | CA9: =BV9/BU9 -> #DIV/0!
A10: 5012 | B10: Andhra Pradesh - South coastal | C10: Guntur | D10: Guntur 1936 | E10: 2 | F10: JAYSAM ESTATES, D.No.9-355, Pulladigunta, Vatticherukuru (Mandal), Guntur District, Pin.522017, A.P. | G10: 15-Nov-2018 | I10: 2198 | BU10: =SUM(J10:U10) -> 0 | BV10: =SUM(V10:AG10) -> 0 | BW10: =SUM(AH10:AS10) -> 0 | BX10: =SUM(AT10:BE10) -> 0 | BY10: =SUM(BF10:BQ10) -> 0 | BZ10: =SUM(BR10:BT10) -> 0 | CA10: =BV10/BU10 -> #DIV/0!
A11: 5048 | B11: Andhra Pradesh - South coastal | C11: Guntur | D11: Guntur 1936 | E11: 3 | F11: JAYSAM ESTATES, D.NO:9-354, Pulladigunta, Vatticherukuru(Mandal), Guntur(District), PIN:522017, A.P. | G11: 15-Dec-2018 | I11: 576 | BU11: =SUM(J11:U11) -> 0 | BV11: =SUM(V11:AG11) -> 0 | BW11: =SUM(AH11:AS11) -> 0 | BX11: =SUM(AT11:BE11) -> 0 | BY11: =SUM(BF11:BQ11) -> 0 | BZ11: =SUM(BR11:BT11) -> 0 | CA11: =BV11/BU11 -> #DIV/0!
A12: 7338 | B12: Andhra Pradesh - South coastal | C12: KALUGOTLAPALLE | D12: KALUGOTLAPALLE 3285 | E12: A | F12: UTTEJITHA RURAL WAREHOUSE GODOWN NO - A , SURVEY NO - 271/2, 273/2B, KALUGOTLAPALLE PANCHAYATI, CHAGALAMARRI MANDAL, NANDYAL - DISTRICT, ANDHRA PRADESH - 518501 | G12: 05-Apr-2026 | I12: 2640 | BR12: 3168 | BS12: 95040 | BT12: 95040 | BU12: =SUM(J12:U12) -> 0 | BV12: =SUM(V12:AG12) -> 0 | BW12: =SUM(AH12:AS12) -> 0 | BX12: =SUM(AT12:BE12) -> 0 | BY12: =SUM(BF12:BQ12) -> 0 | BZ12: =SUM(BR12:BT12) -> 193248 | CA12: =BV12/BU12 -> #DIV/0!
A13: 7339 | B13: Andhra Pradesh - South coastal | C13: KALUGOTLAPALLE | D13: KALUGOTLAPALLE 3285 | E13: B | F13: UTTEJITHA RURAL WAREHOUSE GODOWN NO - B , SURVEY NO - 271/2, 273/2B, KALUGOTLAPALLE PANCHAYATI, CHAGALAMARRI MANDAL, NANDYAL - DISTRICT, ANDHRA PRADESH - 518501 | G13: 08-Apr-2026 | I13: 2640 | BR13: 3168 | BS13: 95040 | BT13: 95040 | BU13: =SUM(J13:U13) -> 0 | BV13: =SUM(V13:AG13) -> 0 | BW13: =SUM(AH13:AS13) -> 0 | BX13: =SUM(AT13:BE13) -> 0 | BY13: =SUM(BF13:BQ13) -> 0 | BZ13: =SUM(BR13:BT13) -> 193248 | CA13: =BV13/BU13 -> #DIV/0!
A14: 7398 | B14: Andhra Pradesh - South coastal | C14: KURNUTHALA | D14: KURNUTHALA 3329 | E14: 1 | F14: UPPUTURI SAMBASIVARAO AGRI GODOWN NO -1, D.NO - 3-53, KURNUTHALA - VILLAGE, VATTICHERUKURU MANDAL, GUNTUR - DIST, ANDHRA PRADESH - 522017 | G14: 22-Apr-2026 | I14: 1655 | BR14: 3309.3333 | BS14: 99280 | BT14: 99280 | BU14: =SUM(J14:U14) -> 0 | BV14: =SUM(V14:AG14) -> 0 | BW14: =SUM(AH14:AS14) -> 0 | BX14: =SUM(AT14:BE14) -> 0 | BY14: =SUM(BF14:BQ14) -> 0 | BZ14: =SUM(BR14:BT14) -> 201869.33 | CA14: =BV14/BU14 -> #DIV/0!
A15: 7385 | B15: Andhra Pradesh - South coastal | C15: PEDAGADELAVARRU | D15: PEDAGADELAVARRU 3297 | E15: 1 | F15: INAMPUDI SUDHARANI GODOWN NO. 1, SURVEY NO - 394-1, PEDAGADELAVARRU VILLAGE, CHINAGADELAVARRU (POST), TSUNDUR MANDAL, BAPATLA DT, ANDHRA PRADESH - 522313 | G15: 10-Apr-2026 | I15: 1667 | BR15: 61250 | BS15: 87500 | BT15: 87500 | BU15: =SUM(J15:U15) -> 0 | BV15: =SUM(V15:AG15) -> 0 | BW15: =SUM(AH15:AS15) -> 0 | BX15: =SUM(AT15:BE15) -> 0 | BY15: =SUM(BF15:BQ15) -> 0 | BZ15: =SUM(BR15:BT15) -> 236250 | CA15: =BV15/BU15 -> #DIV/0!
A16: 7342 | B16: Andhra Pradesh - South coastal | C16: PRATHIPADU | D16: PRATHIPADU 3290 | E16: 1 | F16: SRI BHARATH FERTILISERS GODOWN NO - 1, D.N - 1 - 185, SURVEY NO - 818, MAIN ROAD PRATHIPADU VILLAGE & MANDAL, GUNTUR DIST, ANDHRA PRADESH - 522019 | G16: 10-Apr-2026 | I16: 4889 | BR16: 205338 | BS16: 293340 | BT16: 293340 | BU16: =SUM(J16:U16) -> 0 | BV16: =SUM(V16:AG16) -> 0 | BW16: =SUM(AH16:AS16) -> 0 | BX16: =SUM(AT16:BE16) -> 0 | BY16: =SUM(BF16:BQ16) -> 0 | BZ16: =SUM(BR16:BT16) -> 792018 | CA16: =BV16/BU16 -> #DIV/0!
A17: 6734 | B17: Andhra Pradesh - South coastal | C17: THAMMAVARAM | D17: THAMMAVARAM 2957 | E17: 6A | F17: ONGOLE LOGISTICS PRIVATE LIMITED GODOWNS,GODOWN NO-6A,SURVEY NO 163/1A,163/1C,163/3,164/1A,165,169/1,BODDUVANIPALEM SIVARU ,THAMMAVARAM VILLAGE,KORISAPADU MANADAL,PRAKASAM DT,ANDHRA PRADESH-523212 | G17: 20-Apr-2024 | H17: 19-Mar-2025 | I17: 2500 | AT17: 44000 | AU17: 120000 | AV17: 120000 | AW17: 120000 | AX17: 120000 | AY17: 120000 | AZ17: 120000 | BA17: 120000 | BB17: 120000 | BC17: 120000 | BD17: 120000 | BE17: -65806.452 | BU17: =SUM(J17:U17) -> 0 | BV17: =SUM(V17:AG17) -> 0 | BW17: =SUM(AH17:AS17) -> 0 | BX17: =SUM(AT17:BE17) -> 1178193.5 | BY17: =SUM(BF17:BQ17) -> 0 | BZ17: =SUM(BR17:BT17) -> 0 | CA17: =BV17/BU17 -> #DIV/0!
A18: 6735 | B18: Andhra Pradesh - South coastal | C18: THAMMAVARAM | D18: THAMMAVARAM 2957 | E18: 6B | F18: ONGOLE LOGISTICS PRIVATE LIMITED GODOWNS,GODOWN NO-6B,SURVEY NO 163/1A,163/1C,163/3,164/1A,165,169/1,BODDUVANIPALEM SIVARU ,THAMMAVARAM VILLAGE,KORISAPADU MANADAL,PRAKASAM DT,ANDHRA PRADESH-523212 | G18: 20-Apr-2024 | H18: 19-Mar-2025 | I18: 2500 | AT18: 44000 | AU18: 120000 | AV18: 120000 | AW18: 120000 | AX18: 120000 | AY18: 120000 | AZ18: 120000 | BA18: 120000 | BB18: 120000 | BC18: 120000 | BD18: 120000 | BE18: -65806.452 | BU18: =SUM(J18:U18) -> 0 | BV18: =SUM(V18:AG18) -> 0 | BW18: =SUM(AH18:AS18) -> 0 | BX18: =SUM(AT18:BE18) -> 1178193.5 | BY18: =SUM(BF18:BQ18) -> 0 | BZ18: =SUM(BR18:BT18) -> 0 | CA18: =BV18/BU18 -> #DIV/0!
A19: 7387 | B19: Andhra Pradesh - South coastal | C19: VADLAMUDI | D19: VADLAMUDI 3275 | E19: 3 | F19: K MOHANARAO ESTATES PRIVATE LIMITED WAREHOUSE, GODOWN NO. 3, D.NO. 10 - 280, GUNTUR TENALI ROAD, VADLAMUDI VILLAGE, CHEBROLE MANDAL, GUNTUR DT, ANDHRA PRADESH - 522213 | G19: 01-Apr-2026 | I19: 750 | BR19: 39358 | BS19: 39358 | BT19: 39358 | BU19: =SUM(J19:U19) -> 0 | BV19: =SUM(V19:AG19) -> 0 | BW19: =SUM(AH19:AS19) -> 0 | BX19: =SUM(AT19:BE19) -> 0 | BY19: =SUM(BF19:BQ19) -> 0 | BZ19: =SUM(BR19:BT19) -> 118074 | CA19: =BV19/BU19 -> #DIV/0!
A20: 7388 | B20: Andhra Pradesh - South coastal | C20: VADLAMUDI | D20: VADLAMUDI 3275 | E20: 4 | F20: K MOHANARAO ESTATES PRIVATE LIMITED WAREHOUSE, GODOWN NO. 4, D.NO. 10 - 280, GUNTUR TENALI ROAD, VADLAMUDI VILLAGE, CHEBROLE MANDAL, GUNTUR DT, ANDHRA PRADESH - 522213 | G20: 01-Apr-2026 | I20: 1878 | BR20: 98595 | BS20: 98595 | BT20: 98595 | BU20: =SUM(J20:U20) -> 0 | BV20: =SUM(V20:AG20) -> 0 | BW20: =SUM(AH20:AS20) -> 0 | BX20: =SUM(AT20:BE20) -> 0 | BY20: =SUM(BF20:BQ20) -> 0 | BZ20: =SUM(BR20:BT20) -> 295785 | CA20: =BV20/BU20 -> #DIV/0!
A21: 7386 | B21: Andhra Pradesh - South coastal | C21: VADLAMUDI | D21: VADLAMUDI 3275 | E21: 5 | F21: K MOHANARAO ESTATES PRIVATE LIMITED WAREHOUSE, GODOWN NO. 5, D.NO. 10 - 280, GUNTUR TENALI ROAD, VADLAMUDI VILLAGE, CHEBROLE MANDAL, GUNTUR DT, ANDHRA PRADESH - 522213 | G21: 01-Apr-2026 | I21: 512 | BR21: 26898 | BS21: 26898 | BT21: 26898 | BU21: =SUM(J21:U21) -> 0 | BV21: =SUM(V21:AG21) -> 0 | BW21: =SUM(AH21:AS21) -> 0 | BX21: =SUM(AT21:BE21) -> 0 | BY21: =SUM(BF21:BQ21) -> 0 | BZ21: =SUM(BR21:BT21) -> 80694 | CA21: =BV21/BU21 -> #DIV/0!
A22: 7222 | B22: Andhra Pradesh -North coastal | C22: Balabhadrapuram | D22: BALABHADRAPURAM 3220 | E22: 2A | F22: YAMANA SANTHA KUMARI WAREHOUSE GODOWN NO - 2A, S NO 63 AND 64, DOOR NO 10-149, SRI VIAJAYA DURGA FOOD STORAGES, BALABHADR PURAM VILLAGE, BIKKAVOLU MANDAL, BALABHADRAPURAM B.O, EAST GODAVARI, ANDHRA PRADESH - 533343 | G22: 02-Jan-2026 | I22: 4108 | BO22: 35775 | BP22: 36968 | BQ22: 36968 | BR22: 36968 | BS22: 36968 | BT22: 36968 | BU22: =SUM(J22:U22) -> 0 | BV22: =SUM(V22:AG22) -> 0 | BW22: =SUM(AH22:AS22) -> 0 | BX22: =SUM(AT22:BE22) -> 0 | BY22: =SUM(BF22:BQ22) -> 109711 | BZ22: =SUM(BR22:BT22) -> 110904 | CA22: =BV22/BU22 -> #DIV/0!
A23: 7223 | B23: Andhra Pradesh -North coastal | C23: Balabhadrapuram | D23: BALABHADRAPURAM 3220 | E23: 2B | F23: YAMANA SANTHA KUMARI WAREHOUSE GODOWN NO - 2B, S NO 63 AND 64, DOOR NO 10-149, SRI VIAJAYA DURGA FOOD STORAGES, BALABHADR PURAM VILLAGE, BIKKAVOLU MANDAL, BALABHADRAPURAM B.O, EAST GODAVARI, ANDHRA PRADESH - 533343 | G23: 05-Jan-2026 | I23: 2713 | BO23: 21263 | BP23: 24413 | BQ23: 24413 | BR23: 24413 | BS23: 24413 | BT23: 24413 | BU23: =SUM(J23:U23) -> 0 | BV23: =SUM(V23:AG23) -> 0 | BW23: =SUM(AH23:AS23) -> 0 | BX23: =SUM(AT23:BE23) -> 0 | BY23: =SUM(BF23:BQ23) -> 70089 | BZ23: =SUM(BR23:BT23) -> 73239 | CA23: =BV23/BU23 -> #DIV/0!
A24: 7224 | B24: Andhra Pradesh -North coastal | C24: Balabhadrapuram | D24: BALABHADRAPURAM 3220 | E24: 2C | F24: YAMANA SANTHA KUMARI WAREHOUSE GODOWN NO - 2C, S NO 63 AND 64, DOOR NO 10-149, SRI VIAJAYA DURGA FOOD STORAGES, BALABHADR PURAM VILLAGE, BIKKAVOLU MANDAL, BALABHADRAPURAM B.O, EAST GODAVARI, ANDHRA PRADESH - 533343 | G24: 08-Jan-2026 | I24: 2713 | BO24: 18900 | BP24: 24413 | BQ24: 24413 | BR24: 24413 | BS24: 24413 | BT24: 24413 | BU24: =SUM(J24:U24) -> 0 | BV24: =SUM(V24:AG24) -> 0 | BW24: =SUM(AH24:AS24) -> 0 | BX24: =SUM(AT24:BE24) -> 0 | BY24: =SUM(BF24:BQ24) -> 67726 | BZ24: =SUM(BR24:BT24) -> 73239 | CA24: =BV24/BU24 -> #DIV/0!
A25: 7221 | B25: Andhra Pradesh -North coastal | C25: Balabhadrapuram | D25: BALABHADRAPURAM 3220 | E25: 3C | F25: YAMANA SANTHA KUMARI WAREHOUSE GODOWN NO - 3C, S NO 63 AND 64, DOOR NO 10-151, SRI VIAJAYA DURGA FOOD STORAGES, BALABHADR PURAM VILLAGE, BIKKAVOLU MANDAL, BALABHADRAPURAM B.O, EAST GODAVARI, ANDHRA PRADESH - 533343 | G25: 22-Dec-2025 | I25: 2713 | BN25: 7875 | BO25: 24413 | BP25: 24413 | BQ25: 24413 | BR25: 24413 | BS25: 24413 | BT25: 24413 | BU25: =SUM(J25:U25) -> 0 | BV25: =SUM(V25:AG25) -> 0 | BW25: =SUM(AH25:AS25) -> 0 | BX25: =SUM(AT25:BE25) -> 0 | BY25: =SUM(BF25:BQ25) -> 81114 | BZ25: =SUM(BR25:BT25) -> 73239 | CA25: =BV25/BU25 -> #DIV/0!
A26: 7356 | B26: Andhra Pradesh -North coastal | C26: Gavaravaram | D26: GAVARAVARAM 3304 | E26: 2 | F26: SRI SATYANARAYANA PADDY BOILED UNIT GODOWN NO. 2, DOOR NO. 6-36, R.S.NO - 76/3, NEAR MNR WEIGHBRIDGE, NALLAJARLA ROAD, GAVARAVARAM VILLAGE, KOYYALAGUDEM MANDAL, ELURU - DISTT, AP - 534312 | G26: 13-Apr-2026 | I26: 2408 | BR26: 3371.6667 | BS26: 101150 | BT26: 101150 | BU26: =SUM(J26:U26) -> 0 | BV26: =SUM(V26:AG26) -> 0 | BW26: =SUM(AH26:AS26) -> 0 | BX26: =SUM(AT26:BE26) -> 0 | BY26: =SUM(BF26:BQ26) -> 0 | BZ26: =SUM(BR26:BT26) -> 205671.67 | CA26: =BV26/BU26 -> #DIV/0!
A27: 6693 | B27: Andhra Pradesh -North coastal | C27: VIZIANAGARAM | D27: VIZIANAGARAM 2922 | E27: 2 | F27: PYDA SWAPNA WH, GODOWN NO 2, SURVEY NO 54/1, 54/2, 54/3, BOBBILI ROAD, GOTLAM(V) BONDAPALLI(M) VIZIANAGARAM ANDHRA PRADESH - 535003. | G27: 15-Apr-2024 | H27: 05-Aug-2024 | I27: 4170 | AT27: 66667 | AU27: 125000 | AV27: 125000 | AW27: 125000 | AX27: 4032 | BU27: =SUM(J27:U27) -> 0 | BV27: =SUM(V27:AG27) -> 0 | BW27: =SUM(AH27:AS27) -> 0 | BX27: =SUM(AT27:BE27) -> 445699 | BY27: =SUM(BF27:BQ27) -> 0 | BZ27: =SUM(BR27:BT27) -> 0 | CA27: =BV27/BU27 -> #DIV/0!
A28: 6793 | B28: Assam | C28: Guwahati | D28: GUWAHATI 2947 | E28: 1 | F28: SAKET KUMAR JAIN WH,GODOWN NO 1, DAG NO:241, PATTA NO: 612, REVENUE VILL: 3 NO, MOUZA- RAMPUR, DISTT: KAMRUP, ASSAM PIN: 781001, STATE : ASSAM | G28: 15-May-2024 | H28: 31-Jan-2025 | I28: 3083 | AU28: 126815 | AV28: 231250 | AW28: 231250 | AX28: 231250 | AY28: 231250 | AZ28: 231250 | BA28: 231250 | BB28: 231250 | BC28: 231250 | BU28: =SUM(J28:U28) -> 0 | BV28: =SUM(V28:AG28) -> 0 | BW28: =SUM(AH28:AS28) -> 0 | BX28: =SUM(AT28:BE28) -> 1976815 | BY28: =SUM(BF28:BQ28) -> 0 | BZ28: =SUM(BR28:BT28) -> 0 | CA28: =BV28/BU28 -> #DIV/0!
A29: 6957 | B29: Assam | C29: Guwahati | D29: GUWAHATI 2948 | E29: 1 | F29: SURESH KUMAR JAIN & PRITY SETHI WH,GODOWN NO.1,DAG NO: 193, 313, 314, 315, 317 PATTA NO : 209, 169, 423, 337, 232 VILL- UPARHALI, MOUZA-RAMPUR DISTT: KAMRUP, ASSAM : 781122 STATE: ASSAM | G29: 01-Feb-2025 | I29: 4937 | BD29: 388372 | BE29: 388372 | BF29: 388372 | BG29: 388372 | BH29: 388372 | BI29: 388372 | BJ29: 388372 | BK29: 388372 | BL29: 388372 | BM29: 388372 | BN29: 388372 | BO29: 388372 | BP29: 407330 | BQ29: 407330 | BR29: 407330 | BS29: 407330 | BT29: 407330 | BU29: =SUM(J29:U29) -> 0 | BV29: =SUM(V29:AG29) -> 0 | BW29: =SUM(AH29:AS29) -> 0 | BX29: =SUM(AT29:BE29) -> 776744 | BY29: =SUM(BF29:BQ29) -> 4698380 | BZ29: =SUM(BR29:BT29) -> 1221990 | CA29: =BV29/BU29 -> #DIV/0!
A30: 6775 | B30: Assam | C30: Guwahati | D30: GUWAHATI 2948 | E30: 1 OLD | F30: SURESH KUMAR JAIN & PRITY SETHI WH,GODOWN NO.-1,DAG NO: 193, 313, 314, 315, 317 PATTA NO : 209, 169, 423, 337, 232 VILL- UPARHALI, MOUZA-RAMPUR DISTT: KAMRUP, ASSAM : 781122 STATE: ASSAM | G30: 01-May-2024 | H30: 31-Dec-2024 | I30: 4937 | AU30: 488796 | AV30: 488796 | AW30: 488796 | AX30: 488796 | AY30: 488796 | AZ30: 488796 | BA30: 488796 | BB30: 977592 | BU30: =SUM(J30:U30) -> 0 | BV30: =SUM(V30:AG30) -> 0 | BW30: =SUM(AH30:AS30) -> 0 | BX30: =SUM(AT30:BE30) -> 4399164 | BY30: =SUM(BF30:BQ30) -> 0 | BZ30: =SUM(BR30:BT30) -> 0 | CA30: =BV30/BU30 -> #DIV/0!
A31: 6958 | B31: Assam | C31: Guwahati | D31: GUWAHATI 2948 | E31: 2 | F31: SURESH KUMAR JAIN & PRITY SETHI WH,GODOWN NO. 2, DAG NO: 193, 313, 314, 315, 317 PATTA NO : 209, 169, 423, 337, 232 VILL- UPARHALI, MOUZA-RAMPUR DISTT: KAMRUP, ASSAM : 781122 STATE: ASSAM | G31: 01-Feb-2025 | I31: 6074 | BD31: 477794 | BE31: 477794 | BF31: 477794 | BG31: 477794 | BH31: 477794 | BI31: 477794 | BJ31: 477794 | BK31: 477794 | BL31: 477794 | BM31: 477794 | BN31: 477794 | BO31: 477794 | BP31: 501120 | BQ31: 501120 | BR31: 501120 | BS31: 501120 | BT31: 501120 | BU31: =SUM(J31:U31) -> 0 | BV31: =SUM(V31:AG31) -> 0 | BW31: =SUM(AH31:AS31) -> 0 | BX31: =SUM(AT31:BE31) -> 955588 | BY31: =SUM(BF31:BQ31) -> 5780180 | BZ31: =SUM(BR31:BT31) -> 1503360 | CA31: =BV31/BU31 -> #DIV/0!
A32: 6776 | B32: Assam | C32: Guwahati | D32: GUWAHATI 2948 | E32: 2 OLD | F32: SURESH KUMAR JAIN & PRITY SETHI WH,GODOWN NO.-2,DAG NO: 193, 313, 314, 315, 317 PATTA NO : 209, 169, 423, 337, 232 VILL- UPARHALI, MOUZA-RAMPUR DISTT: KAMRUP, ASSAM : 781122 STATE: ASSAM | G32: 01-May-2024 | H32: 31-Dec-2024 | I32: 6074 | AU32: 601343 | AV32: 601343 | AW32: 601343 | AX32: 601343 | AY32: 601343 | AZ32: 601343 | BA32: 601343 | BU32: =SUM(J32:U32) -> 0 | BV32: =SUM(V32:AG32) -> 0 | BW32: =SUM(AH32:AS32) -> 0 | BX32: =SUM(AT32:BE32) -> 4209401 | BY32: =SUM(BF32:BQ32) -> 0 | BZ32: =SUM(BR32:BT32) -> 0 | CA32: =BV32/BU32 -> #DIV/0!
A33: 7067 | B33: Assam | C33: Guwahati | D33: GUWAHATI 2972 | E33: 1 | F33: LAVIN AGRAWAL & JITENDRA KUMAR AGRAWAL W/H GODOWN NO 1, DAG NO:-377,376 PATT NO:-201,125 VILL:-RAMPUR, MOZA:- RAMPUR DISTT:-KAMRUP, ASSAM-781132 | G33: 01-May-2025 | H33: 30-Nov-2025 | I33: 7449 | BG33: 558663 | BH33: 558663 | BI33: 558663 | BJ33: 558663 | BK33: 558663 | BL33: 558663 | BM33: 558663 | BU33: =SUM(J33:U33) -> 0 | BV33: =SUM(V33:AG33) -> 0 | BW33: =SUM(AH33:AS33) -> 0 | BX33: =SUM(AT33:BE33) -> 0 | BY33: =SUM(BF33:BQ33) -> 3910641 | BZ33: =SUM(BR33:BT33) -> 0 | CA33: =BV33/BU33 -> #DIV/0!
A34: 6777 | B34: Assam | C34: Guwahati | D34: GUWAHATI 2972 | E34: 1 old | F34: LAVIN AGRAWAL & JITENDRA KUMAR AGRAWAL W/H DAG NO:-377,376 PATT NO:-201,125 VILL:-RAMPUR,MOZA:-RAMPUR DISTT:-KAMRUP,ASSAM-781132 | G34: 01-May-2024 | H34: 31-Jan-2025 | I34: 7449 | AU34: 737435 | AV34: 737435 | AW34: 737435 | AX34: 737435 | AY34: 737435 | AZ34: 737435 | BA34: 737435 | BB34: 737435 | BC34: 737435 | BU34: =SUM(J34:U34) -> 0 | BV34: =SUM(V34:AG34) -> 0 | BW34: =SUM(AH34:AS34) -> 0 | BX34: =SUM(AT34:BE34) -> 6636915 | BY34: =SUM(BF34:BQ34) -> 0 | BZ34: =SUM(BR34:BT34) -> 0 | CA34: =BV34/BU34 -> #DIV/0!
A35: 7103 | B35: Assam | C35: Guwahati | D35: GUWAHATI 2974 | E35: 1 | F35: WHEAT PRODUCT COMPANY WH , GOD NO - 1 , DAG NO. 1301,1302,PATTA NO.22,241,VILLAGE: 3 NO RAMPUR,MOUZA: RAMPUR, DISTT - KAMRUP, GUHAWATI 781005, ASSAM | G35: 01-May-2025 | H35: 31-Mar-2026 | I35: 3883 | BG35: 291200 | BH35: 291200 | BI35: 291200 | BJ35: 291200 | BK35: 291200 | BL35: 291200 | BM35: 291200 | BN35: 291200 | BO35: 291200 | BP35: 291200 | BQ35: 291200 | BU35: =SUM(J35:U35) -> 0 | BV35: =SUM(V35:AG35) -> 0 | BW35: =SUM(AH35:AS35) -> 0 | BX35: =SUM(AT35:BE35) -> 0 | BY35: =SUM(BF35:BQ35) -> 3203200 | BZ35: =SUM(BR35:BT35) -> 0 | CA35: =BV35/BU35 -> #DIV/0!
A36: 6783 | B36: Assam | C36: Guwahati | D36: GUWAHATI 2974 | E36: 1 old | F36: WHEAT PRODUCT COMPANY WH , GOD NO - 1 , DAG NO. 1301,1302,PATTA NO.22,241,VILLAGE: 3 NO RAMPUR,MOUZA: RAMPUR, DISTT - KAMRUP, GUHAWATI -781005, ASSAM | G36: 28-Apr-2024 | H36: 28-Feb-2025 | I36: 3883 | AU36: 291200 | AV36: 291200 | AW36: 291200 | AX36: 291200 | AY36: 291200 | AZ36: 291200 | BA36: 291200 | BB36: 291200 | BC36: 291200 | BD36: 291200 | BU36: =SUM(J36:U36) -> 0 | BV36: =SUM(V36:AG36) -> 0 | BW36: =SUM(AH36:AS36) -> 0 | BX36: =SUM(AT36:BE36) -> 2912000 | BY36: =SUM(BF36:BQ36) -> 0 | BZ36: =SUM(BR36:BT36) -> 0 | CA36: =BV36/BU36 -> #DIV/0!
A37: 7362 | B37: Assam | C37: Guwahati | D37: GUWAHATI 2992 | E37: 1 | F37: PUSPA DEVI JAIN WH, GOD NO - 1, DAG NO - 322, PATTA NO - 301, REVENUE VILL - 3 NO, MOUZA - RAMPUR, DISTT - KAMRUP, ASSAM - 781132 | G37: 01-May-2026 | I37: 4164 | BS37: 299796 | BT37: 299796 | BU37: =SUM(J37:U37) -> 0 | BV37: =SUM(V37:AG37) -> 0 | BW37: =SUM(AH37:AS37) -> 0 | BX37: =SUM(AT37:BE37) -> 0 | BY37: =SUM(BF37:BQ37) -> 0 | BZ37: =SUM(BR37:BT37) -> 599592 | CA37: =BV37/BU37 -> #DIV/0!
A38: 6822 | B38: Assam | C38: Guwahati | D38: GUWAHATI 2992 | E38: 1 old | F38: PUSPA DEVI JAIN WH,GODOWN NO. 1, DAG NO. 322,PATTA NO.301,REVENUE VILL:-3 NO,MOUZA: RAMPUR,DISTT:KAMRUP, ASSAM - 781132. | G38: 01-May-2024 | I38: 4164 | AU38: 412220 | AV38: 412220 | AW38: 412220 | AX38: 412220 | AY38: 412220 | AZ38: 412220 | BA38: 412220 | BB38: 412220 | BC38: 412220 | BD38: 412220 | BE38: 412220 | BF38: 424711 | BG38: 424711 | BH38: 424711 | BI38: 424711 | BJ38: 424711 | BK38: 424711 | BL38: 424711 | BM38: 424711 | BU38: =SUM(J38:U38) -> 0 | BV38: =SUM(V38:AG38) -> 0 | BW38: =SUM(AH38:AS38) -> 0 | BX38: =SUM(AT38:BE38) -> 4534420 | BY38: =SUM(BF38:BQ38) -> 3397688 | BZ38: =SUM(BR38:BT38) -> 0 | CA38: =BV38/BU38 -> #DIV/0!
A39: 7144 | B39: Assam | C39: Guwahati | D39: GUWAHATI 3174 | E39: 1 | F39: NRB ASSOCIATES WAREHOUSE GODOWN NO - 1, DAG NO - 649, 674, 620, PATTA NO - 266, 105, 46, VILLAGE - KOCHPARA, MOUZA - CHAYANI, CIRCLE - PALASHBARI, DISTT - KAMRUP, ASSAM - 781128 | G39: 17-May-2025 | H39: 31-Oct-2025 | I39: 2500 | BG39: 127016 | BH39: 262500 | BI39: 262500 | BJ39: 262500 | BK39: 262500 | BL39: 262500 | BU39: =SUM(J39:U39) -> 0 | BV39: =SUM(V39:AG39) -> 0 | BW39: =SUM(AH39:AS39) -> 0 | BX39: =SUM(AT39:BE39) -> 0 | BY39: =SUM(BF39:BQ39) -> 1439516 | BZ39: =SUM(BR39:BT39) -> 0 | CA39: =BV39/BU39 -> #DIV/0!
A40: 7329 | B40: Assam | C40: KAMRUP | D40: KAMRUP 3289 | E40: 1 | F40: KAMAL PREET KAUR WAREHOUSE, GODOWN NO 1, DAG NO 1544, 1545, 1546, 1547, PATT NO 742,743, 744, 745, VILL-3 NO RAMPUR, MAUZA - RAMPUR, CIRCLE- PALASHBARI, DISTRICT- KAMRUP, ASSAM- 781132 | G40: 15-Apr-2026 | I40: 7449 | BR40: 286035 | BS40: 536316 | BT40: 536316 | BU40: =SUM(J40:U40) -> 0 | BV40: =SUM(V40:AG40) -> 0 | BW40: =SUM(AH40:AS40) -> 0 | BX40: =SUM(AT40:BE40) -> 0 | BY40: =SUM(BF40:BQ40) -> 0 | BZ40: =SUM(BR40:BT40) -> 1358667 | CA40: =BV40/BU40 -> #DIV/0!
...
